Workbook

Sheet Movimientos
A1: ID_Mov | B1: Fecha | C1: Producto | D1: Principio Activo/variedad | E1: Tipo | F1: Subtipo | G1: Proveedor | H1: ID_Lote | I1: Tipo_Mov | J1: Cantidad (siempre +) | K1: Cantidad Neta (auto) | L1: Unidad | M1: Fecha Vencimiento | N1: Nro_Remito | O1: Destino / Origen | P1: Nro. Int Finnegans | Q1: Fecha Recep/Mov Finnegans | R1: Columna1 | S1: Columna2 | T1: Lote | U1: Ubicación | V1: Retira
A2: MOV-001 | B2: 46105 | C2: Colza Curry CL | D2: CURRY CL | E2: Semilla | F2: Colza | G2: ERRO | H2: =+T2 -> 260324-001 | I2: ENTRADA | J2: 3400 | K2: =IF(I2="","",IF(I2="ENTRADA",ABS(J2),-ABS(J2))) -> 3400 | L2: kg | N2: 47144 | P2: 14229 | Q2: 46106 | R2: =IF(H2="","",H2&I2) -> 260324-001ENTRADA | S2: =IF(C2="","",C2&I2) -> Colza Curry CLENTRADA | T2: =IF(OR(C2="",I2<>"ENTRADA"),"",TEXT(B2,"AAMMDD")&"-"&TEXT(VALUE(SUBSTITUTE(A2,"MOV-","")),"000")) -> 260324-001 | U2: AP1-2-3
A3: MOV-002 | B3: 46113 | C3: Korvetto | D3: Clopyralid 12% + Halauxyfen methyl 0,51% | E3: Herbicida | F3: Postemergente | G3: GS Agro | H3: =+T3 -> 260401-002 | I3: ENTRADA | J3: 700 | K3: =IF(I3="","",IF(I3="ENTRADA",ABS(J3),-ABS(J3))) -> 700 | L3: L | M3: 46710 | N3: 12383 | P3: 14327 | Q3: 46123 | R3: =IF(H3="","",H3&I3) -> 260401-002ENTRADA | S3: =IF(C3="","",C3&I3) -> KorvettoENTRADA | T3: =IF(OR(C3="",I3<>"ENTRADA"),"",TEXT(B3,"AAMMDD")&"-"&TEXT(VALUE(SUBSTITUTE(A3,"MOV-","")),"000")) -> 260401-002 | U3: AP1
A4: MOV-003 | B4: 46113 | C4: Lontrel | D4: Clopyralid sal monoetanolamina 40.9% | E4: Herbicida | F4: Postemergente | G4: GS Agro | H4: =+T4 -> 260401-003 | I4: ENTRADA | J4: 300 | K4: =IF(I4="","",IF(I4="ENTRADA",ABS(J4),-ABS(J4))) -> 300 | L4: L | M4: 46500 | N4: 12383 | P4: 14327 | Q4: 46123 | R4: =IF(H4="","",H4&I4) -> 260401-003ENTRADA | S4: =IF(C4="","",C4&I4) -> LontrelENTRADA | T4: =IF(OR(C4="",I4<>"ENTRADA"),"",TEXT(B4,"AAMMDD")&"-"&TEXT(VALUE(SUBSTITUTE(A4,"MOV-","")),"000")) -> 260401-003 | U4: A8-N1
A5: MOV-004 | B5: 46113 | C5: Preside | D5: Flumetsulam 11,35% | E5: Herbicida | F5: Preemergente | G5: GS Agro | H5: =+T5 -> 260401-004 | I5: ENTRADA | J5: 2700 | K5: 2700 | L5: L | M5: 46528 | N5: 12383 | P5: 14327 | Q5: 46123 | R5: =IF(H5="","",H5&I5) -> 260401-004ENTRADA | S5: =IF(C5="","",C5&I5) -> PresideENTRADA | T5: =IF(OR(C5="",I5<>"ENTRADA"),"",TEXT(B5,"AAMMDD")&"-"&TEXT(VALUE(SUBSTITUTE(A5,"MOV-","")),"000")) -> 260401-004 | U5: A6 N2-3
A6: MOV-005 | B6: 46113 | C6: Preside | D6: Flumetsulam 11,35% | E6: Herbicida | F6: Preemergente | G6: GS Agro | H6: =+T6 -> 260401-005 | I6: ENTRADA | J6: 100 | K6: =IF(I6="","",IF(I6="ENTRADA",ABS(J6),-ABS(J6))) -> 100 | L6: L | M6: 46761 | N6: 12383 | P6: 14327 | Q6: 46123 | R6: =IF(H6="","",H6&I6) -> 260401-005ENTRADA | S6: =IF(C6="","",C6&I6) -> PresideENTRADA | T6: =IF(OR(C6="",I6<>"ENTRADA"),"",TEXT(B6,"AAMMDD")&"-"&TEXT(VALUE(SUBSTITUTE(A6,"MOV-","")),"000")) -> 260401-005 | U6: A6 N2-3
A7: MOV-006 | B7: 46113 | C7: Tordon 24K | D7: Picloram 24,9% | E7: Herbicida | F7: Postemergente | G7: GS Agro | H7: =+T7 -> 260401-006 | I7: ENTRADA | J7: 300 | K7: =IF(I7="","",IF(I7="ENTRADA",ABS(J7),-ABS(J7))) -> 300 | L7: L | M7: 46517 | N7: 12383 | P7: 14327 | Q7: 46123 | R7: =IF(H7="","",H7&I7) -> 260401-006ENTRADA | S7: =IF(C7="","",C7&I7) -> Tordon 24KENTRADA | T7: =IF(OR(C7="",I7<>"ENTRADA"),"",TEXT(B7,"AAMMDD")&"-"&TEXT(VALUE(SUBSTITUTE(A7,"MOV-","")),"000")) -> 260401-006 | U7: A1 P1
A8: MOV-007 | B8: 46113 | C8: Tronador | D8: Halauxifen metil 3.3% + Aminopyralid 2.7% + Metsulfuron metil 20% | E8: Herbicida | F8: Postemergente | G8: GS Agro | H8: =+T8 -> 260401-007 | I8: ENTRADA | J8: 300 | K8: =IF(I8="","",IF(I8="ENTRADA",ABS(J8),-ABS(J8))) -> 300 | L8: Pack | M8: 46443 | N8: 12383 | P8: 14327 | Q8: 46123 | R8: =IF(H8="","",H8&I8) -> 260401-007ENTRADA | S8: =IF(C8="","",C8&I8) -> TronadorENTRADA | T8: =IF(OR(C8="",I8<>"ENTRADA"),"",TEXT(B8,"AAMMDD")&"-"&TEXT(VALUE(SUBSTITUTE(A8,"MOV-","")),"000")) -> 260401-007 | U8: A7 N1-2
A9: MOV-008 | B9: 46113 | C9: Venceweed extra | D9: 2,4-Db-Butilo 93.1% | E9: Herbicida | F9: Postemergente | G9: GS Agro | H9: =+T9 -> 260401-008 | I9: ENTRADA | J9: 4800 | K9: =IF(I9="","",IF(I9="ENTRADA",ABS(J9),-ABS(J9))) -> 4800 | L9: L | M9: 46737 | N9: 12383 | P9: 14327 | Q9: 46123 | R9: =IF(H9="","",H9&I9) -> 260401-008ENTRADA | S9: =IF(C9="","",C9&I9) -> Venceweed extraENTRADA | T9: =IF(OR(C9="",I9<>"ENTRADA"),"",TEXT(B9,"AAMMDD")&"-"&TEXT(VALUE(SUBSTITUTE(A9,"MOV-","")),"000")) -> 260401-008 | U9: A1-2N1-2
A10: MOV-009 | B10: 46113 | C10: Preside | D10: Flumetsulam 11.35% | E10: Herbicida | F10: Preemergente | G10: GS Agro | H10: 260401-004 | I10: SALIDA | J10: 100 | K10: =IF(I10="","",IF(I10="ENTRADA",ABS(J10),-ABS(J10))) -> -100 | L10: L | N10: 59309 | O10: Salto | P10: 1624 | Q10: 46123 | R10: =IF(H10="","",H10&I10) -> 260401-004SALIDA | S10: =IF(C10="","",C10&I10) -> PresideSALIDA | T10: =IF(OR(C10="",I10<>"ENTRADA"),"",TEXT(B10,"AAMMDD")&"-"&TEXT(VALUE(SUBSTITUTE(A10,"MOV-","")),"000"))
A11: MOV-010 | B11: 46113 | C11: Venceweed extra | D11: 2,4-Db-Butilo 93.1% | E11: Herbicida | F11: Postemergente | H11: 260401-008 | I11: SALIDA | J11: 360 | K11: =IF(I11="","",IF(I11="ENTRADA",ABS(J11),-ABS(J11))) -> -360 | L11: L | N11: 59309 | O11: Salto | P11: 1624 | Q11: 46123 | R11: =IF(H11="","",H11&I11) -> 260401-008SALIDA | S11: =IF(C11="","",C11&I11) -> Venceweed extraSALIDA | T11: =IF(OR(C11="",I11<>"ENTRADA"),"",TEXT(B11,"AAMMDD")&"-"&TEXT(VALUE(SUBSTITUTE(A11,"MOV-","")),"000"))
A12: MOV-011 | B12: 46118 | C12: Silobolsa | D12: Silobolsa 9 pies | E12: Silobolsa | G12: AYP Agrogestiones | H12: =+T12 -> 260406-011 | I12: ENTRADA | J12: 3 | K12: =IF(I12="","",IF(I12="ENTRADA",ABS(J12),-ABS(J12))) -> 3 | L12: unidad | N12: 3141 | P12: 14311 | Q12: 46122 | R12: =IF(H12="","",H12&I12) -> 260406-011ENTRADA | S12: =IF(C12="","",C12&I12) -> SilobolsaENTRADA | T12: =IF(OR(C12="",I12<>"ENTRADA"),"",TEXT(B12,"AAMMDD")&"-"&TEXT(VALUE(SUBSTITUTE(A12,"MOV-","")),"000")) -> 260406-011
A13: MOV-012 | B13: 46119 | C13: Dedalo elite | D13: 2,4 D Acido 27.2% | E13: Herbicida | F13: Postemergente | G13: Agromil | H13: =+T13 -> 260407-012 | I13: ENTRADA | J13: 12500 | K13: =IF(I13="","",IF(I13="ENTRADA",ABS(J13),-ABS(J13))) -> 12500 | L13: L | M13: 46725 | N13: 69750 | P13: 14291 | Q13: 46119 | R13: =IF(H13="","",H13&I13) -> 260407-012ENTRADA | S13: =IF(C13="","",C13&I13) -> Dedalo eliteENTRADA | T13: =IF(OR(C13="",I13<>"ENTRADA"),"",TEXT(B13,"AAMMDD")&"-"&TEXT(VALUE(SUBSTITUTE(A13,"MOV-","")),"000")) -> 260407-012 | U13: B1-2-3-4N1-2
A14: MOV-013 | B14: 46120 | C14: Raigrás E284 | D14: Estanzuela 284 | E14: Semilla | F14: Raigrás | G14: Granicor | H14: =+T14 -> 260408-013 | I14: ENTRADA | J14: 14000 | K14: =IF(I14="","",IF(I14="ENTRADA",ABS(J14),-ABS(J14))) -> 14000 | L14: kg | N14: 42865 | P14: 14310 | Q14: 46122 | R14: =IF(H14="","",H14&I14) -> 260408-013ENTRADA | S14: =IF(C14="","",C14&I14) -> Raigrás E284ENTRADA | T14: =IF(OR(C14="",I14<>"ENTRADA"),"",TEXT(B14,"AAMMDD")&"-"&TEXT(VALUE(SUBSTITUTE(A14,"MOV-","")),"000")) -> 260408-013 | U14: piso
A15: MOV-014 | B15: 46120 | C15: Starane Xtra | D15: Fluroxypyr Meptil 45,52% | E15: Herbicida | F15: Postemergente | G15: GS Agro | H15: =+T15 -> 260408-014 | I15: ENTRADA | J15: 1140 | K15: =IF(I15="","",IF(I15="ENTRADA",ABS(J15),-ABS(J15))) -> 1140 | L15: L | M15: 46509 | N15: 12416 | P15: 14326 | Q15: 46123 | R15: =IF(H15="","",H15&I15) -> 260408-014ENTRADA | S15: =IF(C15="","",C15&I15) -> Starane XtraENTRADA | T15: =IF(OR(C15="",I15<>"ENTRADA"),"",TEXT(B15,"AAMMDD")&"-"&TEXT(VALUE(SUBSTITUTE(A15,"MOV-","")),"000")) -> 260408-014 | U15: A-7 N-2
A16: MOV-015 | B16: 46120 | C16: Pixxaro | D16: Fluroxypyr meptyl 34,91% + Halauxyfen methyl 1.64% + Cloquintocet mexyl 1.57% | E16: Herbicida | F16: Postemergente | G16: GS Agro | H16: =+T16 -> 260408-015 | I16: ENTRADA | J16: 500 | K16: =IF(I16="","",IF(I16="ENTRADA",ABS(J16),-ABS(J16))) -> 500 | L16: L | M16: 46397 | N16: 12416 | P16: 14326 | Q16: 46123 | R16: =IF(H16="","",H16&I16) -> 260408-015ENTRADA | S16: =IF(C16="","",C16&I16) -> PixxaroENTRADA | T16: =IF(OR(C16="",I16<>"ENTRADA"),"",TEXT(B16,"AAMMDD")&"-"&TEXT(VALUE(SUBSTITUTE(A16,"MOV-","")),"000")) -> 260408-015 | U16: A-9N-1
A17: MOV-016 | B17: 46120 | C17: Dedalo elite | D17: 2,4 D Acido 27.2% | E17: Herbicida | F17: Postemergente | G17: Agromil | H17: 260407-012 | I17: SALIDA | J17: 600 | K17: =IF(I17="","",IF(I17="ENTRADA",ABS(J17),-ABS(J17))) -> -600 | L17: L | N17: 59310 | O17: Durazno | P17: 1625 | Q17: 46123 | R17: =IF(H17="","",H17&I17) -> 260407-012SALIDA | S17: =IF(C17="","",C17&I17) -> Dedalo eliteSALIDA | T17: =IF(OR(C17="",I17<>"ENTRADA"),"",TEXT(B17,"AAMMDD")&"-"&TEXT(VALUE(SUBSTITUTE(A17,"MOV-","")),"000"))
A18: MOV-017 | B18: 46120 | C18: Tronador | D18: Halauxifen metil 3.3% + Aminopyralid 2.7% + Metsulfuron metil 20% | E18: Herbicida | F18: Postemergente | H18: 260401-007 | I18: SALIDA | J18: 15 | K18: =IF(I18="","",IF(I18="ENTRADA",ABS(J18),-ABS(J18))) -> -15 | L18: Pack | N18: 59310 | O18: Durazno | P18: 1625 | Q18: 46123 | R18: =IF(H18="","",H18&I18) -> 260401-007SALIDA | S18: =IF(C18="","",C18&I18) -> TronadorSALIDA | T18: =IF(OR(C18="",I18<>"ENTRADA"),"",TEXT(B18,"AAMMDD")&"-"&TEXT(VALUE(SUBSTITUTE(A18,"MOV-","")),"000"))
A19: MOV-018 | B19: 46120 | C19: Preside | D19: Flumetsulam 11.35% | E19: Herbicida | F19: Preemergente | G19: GS Agro | H19: 260401-004 | I19: SALIDA | J19: 560 | K19: =IF(I19="","",IF(I19="ENTRADA",ABS(J19),-ABS(J19))) -> -560 | L19: L | N19: 59310 | O19: Durazno | P19: 1625 | Q19: 46123 | R19: =IF(H19="","",H19&I19) -> 260401-004SALIDA | S19: =IF(C19="","",C19&I19) -> PresideSALIDA | T19: =IF(OR(C19="",I19<>"ENTRADA"),"",TEXT(B19,"AAMMDD")&"-"&TEXT(VALUE(SUBSTITUTE(A19,"MOV-","")),"000"))
A20: MOV-019 | B20: 46120 | C20: Starane Xtra | D20: Fluroxypyr Meptil 45,52% | E20: Herbicida | F20: Postemergente | G20: GS Agro | H20: 260408-014 | I20: SALIDA | J20: 600 | K20: =IF(I20="","",IF(I20="ENTRADA",ABS(J20),-ABS(J20))) -> -600 | L20: L | N20: 59310 | O20: Durazno | P20: 1625 | Q20: 46123 | R20: =IF(H20="","",H20&I20) -> 260408-014SALIDA | S20: =IF(C20="","",C20&I20) -> Starane XtraSALIDA | T20: =IF(OR(C20="",I20<>"ENTRADA"),"",TEXT(B20,"AAMMDD")&"-"&TEXT(VALUE(SUBSTITUTE(A20,"MOV-","")),"000"))
A21: MOV-020 | B21: 46120 | C21: Venceweed extra | D21: 2,4-Db-Butilo 93.1% | E21: Herbicida | F21: Postemergente | H21: 260401-008 | I21: SALIDA | J21: 2100 | K21: =IF(I21="","",IF(I21="ENTRADA",ABS(J21),-ABS(J21))) -> -2100 | L21: L | N21: 59310 | O21: Durazno | P21: 1625 | Q21: 46123 | R21: =IF(H21="","",H21&I21) -> 260401-008SALIDA | S21: =IF(C21="","",C21&I21) -> Venceweed extraSALIDA | T21: =IF(OR(C21="",I21<>"ENTRADA"),"",TEXT(B21,"AAMMDD")&"-"&TEXT(VALUE(SUBSTITUTE(A21,"MOV-","")),"000"))
A22: MOV-021 | B22: 46120 | C22: Pixxaro | D22: Fluroxypyr meptyl 34,91% + Halauxyfen methyl 1.64% + Cloquintocet mexyl 1.57% | E22: Herbicida | F22: Postemergente | G22: GS Agro | H22: 260408-015 | I22: SALIDA | J22: 300 | K22: =IF(I22="","",IF(I22="ENTRADA",ABS(J22),-ABS(J22))) -> -300 | L22: L | N22: 59310 | O22: Durazno | P22: 1625 | Q22: 46123 | R22: =IF(H22="","",H22&I22) -> 260408-015SALIDA | S22: =IF(C22="","",C22&I22) -> PixxaroSALIDA | T22: =IF(OR(C22="",I22<>"ENTRADA"),"",TEXT(B22,"AAMMDD")&"-"&TEXT(VALUE(SUBSTITUTE(A22,"MOV-","")),"000"))
A23: MOV-022 | B23: 46120 | C23: Korvetto | D23: Clopyralid 12% + Halauxyfen methyl 0.51% | E23: Herbicida | F23: Postemergente | H23: 260401-002 | I23: SALIDA | J23: 200 | K23: =IF(I23="","",IF(I23="ENTRADA",ABS(J23),-ABS(J23))) -> -200 | L23: L | N23: 59310 | O23: Durazno | P23: 1625 | Q23: 46123 | R23: =IF(H23="","",H23&I23) -> 260401-002SALIDA | S23: =IF(C23="","",C23&I23) -> KorvettoSALIDA | T23: =IF(OR(C23="",I23<>"ENTRADA"),"",TEXT(B23,"AAMMDD")&"-"&TEXT(VALUE(SUBSTITUTE(A23,"MOV-","")),"000"))
A24: MOV-023 | B24: 46122 | C24: Colza Hyola 575 CL | D24: HYOLA 575 CL | E24: Semilla | F24: Colza | G24: ERRO | H24: =+T24 -> 260410-023 | I24: ENTRADA | J24: 2860 | K24: =IF(I24="","",IF(I24="ENTRADA",ABS(J24),-ABS(J24))) -> 2860 | L24: kg | N24: 47418 | P24: 14331 | Q24: 13/0472026 | R24: =IF(H24="","",H24&I24) -> 260410-023ENTRADA | S24: =IF(C24="","",C24&I24) -> Colza Hyola 575 CLENTRADA | T24: =IF(OR(C24="",I24<>"ENTRADA"),"",TEXT(B24,"AAMMDD")&"-"&TEXT(VALUE(SUBSTITUTE(A24,"MOV-","")),"000")) -> 260410-023
A25: MOV-024 | B25: 46122 | C25: Colza Apolo CL | D25: APOLO CL | E25: Semilla | F25: Colza | G25: ERRO | H25: =+T25 -> 260410-024 | I25: ENTRADA | J25: 200 | K25: =IF(I25="","",IF(I25="ENTRADA",ABS(J25),-ABS(J25))) -> 200 | L25: kg | N25: 47413 | P25: 14330 | Q25: 46125 | R25: =IF(H25="","",H25&I25) -> 260410-024ENTRADA | S25: =IF(C25="","",C25&I25) -> Colza Apolo CLENTRADA | T25: =IF(OR(C25="",I25<>"ENTRADA"),"",TEXT(B25,"AAMMDD")&"-"&TEXT(VALUE(SUBSTITUTE(A25,"MOV-","")),"000")) -> 260410-024
A26: MOV-025 | B26: 46122 | C26: Azuka | D26: Glifosato Sal DMA 608 g/L. Equivalente en glifosato 480 g/L | E26: Herbicida | F26: Postemergente | G26: Proquimur | H26: =+T26 -> 260410-025 | I26: ENTRADA | J26: 21120 | K26: =IF(I26="","",IF(I26="ENTRADA",ABS(J26),-ABS(J26))) -> 21120 | L26: L | M26: 46692 | N26: 48776 | P26: 14328 | Q26: 46123 | R26: =IF(H26="","",H26&I26) -> 260410-025ENTRADA | S26: =IF(C26="","",C26&I26) -> AzukaENTRADA | T26: =IF(OR(C26="",I26<>"ENTRADA"),"",TEXT(B26,"AAMMDD")&"-"&TEXT(VALUE(SUBSTITUTE(A26,"MOV-","")),"000")) -> 260410-025 | U26: C1-2-3-4-5-6-7-8N1-2
A27: MOV-026 | B27: 46122 | C27: Azuka | D27: Glifosato Sal DMA 608 g/L. Equivalente en glifosato 480 g/L | E27: Herbicida | F27: Postemergente | G27: Proquimur | H27: 260410-025 | I27: ENTRADA | J27: 2880 | K27: =IF(I27="","",IF(I27="ENTRADA",ABS(J27),-ABS(J27))) -> 2880 | L27: L | M27: 46692 | N27: 48786 | P27: 14329 | Q27: 46123 | R27: =IF(H27="","",H27&I27) -> 260410-025ENTRADA | S27: =IF(C27="","",C27&I27) -> AzukaENTRADA | T27: =IF(OR(C27="",I27<>"ENTRADA"),"",TEXT(B27,"AAMMDD")&"-"&TEXT(VALUE(SUBSTITUTE(A27,"MOV-","")),"000")) -> 260410-026 | U27: C1-2-3-4-5-6-7-8N1-2
A28: MOV-027 | B28: 46122 | C28: Pardo | D28: Clethodim 240 g/L | E28: Herbicida | F28: Postemergente | G28: Proquimur | H28: =+T28 -> 260410-027 | I28: ENTRADA | J28: 17940 | K28: =IF(I28="","",IF(I28="ENTRADA",ABS(J28),-ABS(J28))) -> 17940 | L28: L | M28: 46753 | N28: 48786 | P28: 14329 | Q28: 46123 | R28: =IF(H28="","",H28&I28) -> 260410-027ENTRADA | S28: =IF(C28="","",C28&I28) -> PardoENTRADA | T28: =IF(OR(C28="",I28<>"ENTRADA"),"",TEXT(B28,"AAMMDD")&"-"&TEXT(VALUE(SUBSTITUTE(A28,"MOV-","")),"000")) -> 260410-027 | U28: B4-5-6-7-8N1-2
A29: MOV-078 | B29: 46122 | C29: Avena | D29: Avena propia | E29: Semilla | F29: Avena | H29: =+T29 -> 260410-078 | I29: ENTRADA | J29: 30000 | K29: =IF(I29="","",IF(I29="ENTRADA",ABS(J29),-ABS(J29))) -> 30000 | L29: kg | N29: 59237 | O29: Durazno | R29: =IF(H29="","",H29&I29) -> 260410-078ENTRADA | S29: =IF(C29="","",C29&I29) -> Avena ENTRADA | T29: =IF(OR(C29="",I29<>"ENTRADA"),"",TEXT(B29,"AAMMDD")&"-"&TEXT(VALUE(SUBSTITUTE(A29,"MOV-","")),"000")) -> 260410-078
A30: MOV-028 | B30: 46126 | C30: Harrier | D30: ALCOHOL LINEAL ETOXILADO 32.7% | E30: Coadyuvante | G30: Don asdrual | H30: =+T30 -> 260414-028 | I30: ENTRADA | J30: 1000 | K30: =IF(I30="","",IF(I30="ENTRADA",ABS(J30),-ABS(J30))) -> 1000 | L30: L | M30: 46661 | N30: 390 | P30: 14339 | Q30: 46127 | R30: =IF(H30="","",H30&I30) -> 260414-028ENTRADA | S30: =IF(C30="","",C30&I30) -> HarrierENTRADA | T30: =IF(OR(C30="",I30<>"ENTRADA"),"",TEXT(B30,"AAMMDD")&"-"&TEXT(VALUE(SUBSTITUTE(A30,"MOV-","")),"000")) -> 260414-028 | U30: A3-4-5-6N1-2-3
A31: MOV-029 | B31: 46126 | C31: Harrier | D31: ALCOHOL LINEAL ETOXILADO 32.7% | E31: Coadyuvante | G31: Don asdrual | H31: =+T31 -> 260414-029 | I31: ENTRADA | J31: 5000 | K31: =IF(I31="","",IF(I31="ENTRADA",ABS(J31),-ABS(J31))) -> 5000 | L31: L | M31: 46813 | N31: 390 | P31: 14339 | Q31: 46127 | R31: =IF(H31="","",H31&I31) -> 260414-029ENTRADA | S31: =IF(C31="","",C31&I31) -> HarrierENTRADA | T31: =IF(OR(C31="",I31<>"ENTRADA"),"",TEXT(B31,"AAMMDD")&"-"&TEXT(VALUE(SUBSTITUTE(A31,"MOV-","")),"000")) -> 260414-029 | U31: A3-4-5-6N1-2-3
A32: MOV-030 | B32: 46126 | C32: Full control | D32: ACIDO FOSFORICO 23 g | E32: Coadyuvante | G32: Don asdrual | H32: =+T32 -> 260414-030 | I32: ENTRADA | J32: 1200 | K32: =IF(I32="","",IF(I32="ENTRADA",ABS(J32),-ABS(J32))) -> 1200 | L32: L | M32: 46661 | N32: 390 | P32: 14339 | Q32: 46127 | R32: =IF(H32="","",H32&I32) -> 260414-030ENTRADA | S32: =IF(C32="","",C32&I32) -> Full controlENTRADA | T32: =IF(OR(C32="",I32<>"ENTRADA"),"",TEXT(B32,"AAMMDD")&"-"&TEXT(VALUE(SUBSTITUTE(A32,"MOV-","")),"000")) -> 260414-030 | U32: A7-8N3
A33: MOV-031 | B33: 46126 | C33: Maxi Drop | D33: ACEITE DE SOJA 48 g | E33: Coadyuvante | G33: Don asdrual | H33: =+T33 -> 260414-031 | I33: ENTRADA | J33: 195 | K33: =IF(I33="","",IF(I33="ENTRADA",ABS(J33),-ABS(J33))) -> 195 | L33: L | M33: 46388 | N33: 390 | P33: 14339 | Q33: 46127 | R33: =IF(H33="","",H33&I33) -> 260414-031ENTRADA | S33: =IF(C33="","",C33&I33) -> Maxi DropENTRADA | T33: =IF(OR(C33="",I33<>"ENTRADA"),"",TEXT(B33,"AAMMDD")&"-"&TEXT(VALUE(SUBSTITUTE(A33,"MOV-","")),"000")) -> 260414-031 | U33: A-6N-1
A34: MOV-081 | B34: 46126 | C34: Avena | D34: Avena propia | E34: Semilla | F34: Avena | H34: 260410-078 | I34: ENTRADA | J34: 30000 | K34: =IF(I34="","",IF(I34="ENTRADA",ABS(J34),-ABS(J34))) -> 30000 | L34: kg | N34: 59238 | O34: Durazno | R34: =IF(H34="","",H34&I34) -> 260410-078ENTRADA | S34: =IF(C34="","",C34&I34) -> Avena ENTRADA | T34: =IF(OR(C34="",I34<>"ENTRADA"),"",TEXT(B34,"AAMMDD")&"-"&TEXT(VALUE(SUBSTITUTE(A34,"MOV-","")),"000")) -> 260414-081
A35: MOV-032 | B35: 46127 | C35: Axial | D35: PINOXADEN 5 GR + CLOQUINTOCET-MEXIL 1.25 GR | E35: Herbicida | F35: Postemergente | G35: GS Agro | H35: =+T35 -> 260415-032 | I35: ENTRADA | J35: 2000 | K35: =IF(I35="","",IF(I35="ENTRADA",ABS(J35),-ABS(J35))) -> 2000 | L35: L | M35: 46419 | N35: 12482 | P35: 14340 | Q35: 46127 | R35: =IF(H35="","",H35&I35) -> 260415-032ENTRADA | S35: =IF(C35="","",C35&I35) -> AxialENTRADA | T35: =IF(OR(C35="",I35<>"ENTRADA"),"",TEXT(B35,"AAMMDD")&"-"&TEXT(VALUE(SUBSTITUTE(A35,"MOV-","")),"000")) -> 260415-032 | U35: A9N1-2-3
A36: MOV-033 | B36: 46127 | C36: Raigrás E284 | D36: Estanzuela 284 | E36: Semilla | F36: Raigrás | G36: Granicor | H36: 260408-013 | I36: SALIDA | J36: 1250 | K36: =IF(I36="","",IF(I36="ENTRADA",ABS(J36),-ABS(J36))) -> -1250 | L36: kg | N36: 59311 | O36: Lit. Norte | P36: 1628 | Q36: 46127 | R36: =IF(H36="","",H36&I36) -> 260408-013SALIDA | S36: =IF(C36="","",C36&I36) -> Raigrás E284SALIDA | T36: =IF(OR(C36="",I36<>"ENTRADA"),"",TEXT(B36,"AAMMDD")&"-"&TEXT(VALUE(SUBSTITUTE(A36,"MOV-","")),"000"))
A37: MOV-034 | B37: 46128 | C37: Silobolsa | D37: Silobolsa 9 pies | E37: Silobolsa | G37: AYP Agrogestiones | H37: 260406-011 | I37: ENTRADA | J37: 30 | K37: =IF(I37="","",IF(I37="ENTRADA",ABS(J37),-ABS(J37))) -> 30 | L37: unidad | N37: 3160 | P37: 14365 | Q37: 46137 | R37: =IF(H37="","",H37&I37) -> 260406-011ENTRADA | S37: =IF(C37="","",C37&I37) -> SilobolsaENTRADA | T37: =IF(OR(C37="",I37<>"ENTRADA"),"",TEXT(B37,"AAMMDD")&"-"&TEXT(VALUE(SUBSTITUTE(A37,"MOV-","")),"000")) -> 260416-034
A38: MOV-035 | B38: 46128 | C38: Colza Nuola 300 | D38: Nuola 300 | E38: Semilla | F38: Colza | G38: Agroterra | H38: =+T38 -> 260416-035 | I38: ENTRADA | J38: 3200 | K38: =IF(I38="","",IF(I38="ENTRADA",ABS(J38),-ABS(J38))) -> 3200 | L38: kg | N38: 30271 | P38: 14363 | Q38: 46137 | R38: =IF(H38="","",H38&I38) -> 260416-035ENTRADA | S38: =IF(C38="","",C38&I38) -> Colza Nuola 300ENTRADA | T38: =IF(OR(C38="",I38<>"ENTRADA"),"",TEXT(B38,"AAMMDD")&"-"&TEXT(VALUE(SUBSTITUTE(A38,"MOV-","")),"000")) -> 260416-035
A39: MOV-036 | B39: 46128 | C39: Colza Ceres IMI | D39: Ceres IMI | E39: Semilla | F39: Colza | G39: Agroterra | H39: =+T39 -> 260416-036 | I39: ENTRADA | J39: 1520 | K39: =IF(I39="","",IF(I39="ENTRADA",ABS(J39),-ABS(J39))) -> 1520 | L39: kg | N39: 30279 | P39: 14364 | Q39: 46137 | R39: =IF(H39="","",H39&I39) -> 260416-036ENTRADA | S39: =IF(C39="","",C39&I39) -> Colza Ceres IMIENTRADA | T39: =IF(OR(C39="",I39<>"ENTRADA"),"",TEXT(B39,"AAMMDD")&"-"&TEXT(VALUE(SUBSTITUTE(A39,"MOV-","")),"000")) -> 260416-036 | U39: A1/N3
A40: MOV-037 | B40: 46129 | C40: Festuca Carape | D40: Festuca Carape | E40: Semilla | F40: Festuca | G40: Megaagro | H40: =+T40 -> 260417-037 | I40: ENTRADA | J40: 3400 | K40: =IF(I40="","",IF(I40="ENTRADA",ABS(J40),-ABS(J40))) -> 3400 | L40: kg | N40: 94518 | P40: 14410 | Q40: 46140 | R40: =IF(H40="","",H40&I40) -> 260417-037ENTRADA | S40: =IF(C40="","",C40&I40) -> Festuca CarapeENTRADA | T40: =IF(OR(C40="",I40<>"ENTRADA"),"",TEXT(B40,"AAMMDD")&"-"&TEXT(VALUE(SUBSTITUTE(A40,"MOV-","")),"000")) -> 260417-037
...

Sheet Resumen_Producto
A1: Producto | B1: Principio Activo/Variedad | C1: Tipo | D1: Subtipo | E1: Unidad | F1: Lotes Activos | G1: Stock Total | H1: Venc. Más Próximo
A2: Colza Curry CL | B2: =IF(A2="","",IFERROR(INDEX(Movimientos!$D$2:$D$1993,MATCH(A2&"ENTRADA",Movimientos!$S$2:$S$1993,0)),"-")) -> CURRY CL | C2: =IF(A2="","",IFERROR(INDEX(Movimientos!$E$2:$E$1993,MATCH(A2&"ENTRADA",Movimientos!$S$2:$S$1993,0)),"-")) -> Semilla | D2: =IF(A2="","",IFERROR(INDEX(Movimientos!$F$2:$F$1993,MATCH(A2&"ENTRADA",Movimientos!$S$2:$S$1993,0)),"-")) -> Colza | E2: =IF(A2="","",IFERROR(INDEX(Movimientos!$L$2:$L$1993,MATCH(A2&"ENTRADA",Movimientos!$S$2:$S$1993,0)),"-")) -> kg | F2: =IF(A2="","",COUNTIFS(Stock_por_Lote!$B:$B,A2,Stock_por_Lote!$J:$J,">0")) -> 0 | G2: =IF(A2="","",SUMIFS(Movimientos!$K:$K,Movimientos!$C:$C,A2)) -> 0 | H2: =IF(A2="","",IFERROR(IF(_xlfn.MINIFS(Stock_por_Lote!$H:$H,Stock_por_Lote!$B:$B,A2,Stock_por_Lote!$J:$J,">0")=0,"S/D",_xlfn.MINIFS(Stock_por_Lote!$H:$H,Stock_por_Lote!$B:$B,A2,Stock_por_Lote!$J:$J,">0")),"S/D")) -> S/D
A3: Korvetto | B3: =IF(A3="","",IFERROR(INDEX(Movimientos!$D$2:$D$1993,MATCH(A3&"ENTRADA",Movimientos!$S$2:$S$1993,0)),"-")) -> Clopyralid 12% + Halauxyfen methyl 0,51% | C3: =IF(A3="","",IFERROR(INDEX(Movimientos!$E$2:$E$1993,MATCH(A3&"ENTRADA",Movimientos!$S$2:$S$1993,0)),"-")) -> Herbicida | D3: =IF(A3="","",IFERROR(INDEX(Movimientos!$F$2:$F$1993,MATCH(A3&"ENTRADA",Movimientos!$S$2:$S$1993,0)),"-")) -> Postemergente | E3: =IF(A3="","",IFERROR(INDEX(Movimientos!$L$2:$L$1993,MATCH(A3&"ENTRADA",Movimientos!$S$2:$S$1993,0)),"-")) -> L | F3: =IF(A3="","",COUNTIFS(Stock_por_Lote!$B:$B,A3,Stock_por_Lote!$J:$J,">0")) -> 1 | G3: =IF(A3="","",SUMIFS(Movimientos!$K:$K,Movimientos!$C:$C,A3)) -> 10 | H3: =IF(A3="","",IFERROR(IF(_xlfn.MINIFS(Stock_por_Lote!$H:$H,Stock_por_Lote!$B:$B,A3,Stock_por_Lote!$J:$J,">0")=0,"S/D",_xlfn.MINIFS(Stock_por_Lote!$H:$H,Stock_por_Lote!$B:$B,A3,Stock_por_Lote!$J:$J,">0")),"S/D")) -> 46710
A4: Lontrel | B4: =IF(A4="","",IFERROR(INDEX(Movimientos!$D$2:$D$1993,MATCH(A4&"ENTRADA",Movimientos!$S$2:$S$1993,0)),"-")) -> Clopyralid sal monoetanolamina 40.9% | C4: =IF(A4="","",IFERROR(INDEX(Movimientos!$E$2:$E$1993,MATCH(A4&"ENTRADA",Movimientos!$S$2:$S$1993,0)),"-")) -> Herbicida | D4: =IF(A4="","",IFERROR(INDEX(Movimientos!$F$2:$F$1993,MATCH(A4&"ENTRADA",Movimientos!$S$2:$S$1993,0)),"-")) -> Postemergente | E4: =IF(A4="","",IFERROR(INDEX(Movimientos!$L$2:$L$1993,MATCH(A4&"ENTRADA",Movimientos!$S$2:$S$1993,0)),"-")) -> L | F4: =IF(A4="","",COUNTIFS(Stock_por_Lote!$B:$B,A4,Stock_por_Lote!$J:$J,">0")) -> 1 | G4: =IF(A4="","",SUMIFS(Movimientos!$K:$K,Movimientos!$C:$C,A4)) -> 255 | H4: =IF(A4="","",IFERROR(IF(_xlfn.MINIFS(Stock_por_Lote!$H:$H,Stock_por_Lote!$B:$B,A4,Stock_por_Lote!$J:$J,">0")=0,"S/D",_xlfn.MINIFS(Stock_por_Lote!$H:$H,Stock_por_Lote!$B:$B,A4,Stock_por_Lote!$J:$J,">0")),"S/D")) -> 46500
A5: Preside | B5: =IF(A5="","",IFERROR(INDEX(Movimientos!$D$2:$D$1993,MATCH(A5&"ENTRADA",Movimientos!$S$2:$S$1993,0)),"-")) -> Flumetsulam 11,35% | C5: =IF(A5="","",IFERROR(INDEX(Movimientos!$E$2:$E$1993,MATCH(A5&"ENTRADA",Movimientos!$S$2:$S$1993,0)),"-")) -> Herbicida | D5: =IF(A5="","",IFERROR(INDEX(Movimientos!$F$2:$F$1993,MATCH(A5&"ENTRADA",Movimientos!$S$2:$S$1993,0)),"-")) -> Preemergente | E5: =IF(A5="","",IFERROR(INDEX(Movimientos!$L$2:$L$1993,MATCH(A5&"ENTRADA",Movimientos!$S$2:$S$1993,0)),"-")) -> L | F5: =IF(A5="","",COUNTIFS(Stock_por_Lote!$B:$B,A5,Stock_por_Lote!$J:$J,">0")) -> 2 | G5: =IF(A5="","",SUMIFS(Movimientos!$K:$K,Movimientos!$C:$C,A5)) -> 1920 | H5: =IF(A5="","",IFERROR(IF(_xlfn.MINIFS(Stock_por_Lote!$H:$H,Stock_por_Lote!$B:$B,A5,Stock_por_Lote!$J:$J,">0")=0,"S/D",_xlfn.MINIFS(Stock_por_Lote!$H:$H,Stock_por_Lote!$B:$B,A5,Stock_por_Lote!$J:$J,">0")),"S/D")) -> 46528
A6: Tordon 24K | B6: =IF(A6="","",IFERROR(INDEX(Movimientos!$D$2:$D$1993,MATCH(A6&"ENTRADA",Movimientos!$S$2:$S$1993,0)),"-")) -> Picloram 24,9% | C6: =IF(A6="","",IFERROR(INDEX(Movimientos!$E$2:$E$1993,MATCH(A6&"ENTRADA",Movimientos!$S$2:$S$1993,0)),"-")) -> Herbicida | D6: =IF(A6="","",IFERROR(INDEX(Movimientos!$F$2:$F$1993,MATCH(A6&"ENTRADA",Movimientos!$S$2:$S$1993,0)),"-")) -> Postemergente | E6: =IF(A6="","",IFERROR(INDEX(Movimientos!$L$2:$L$1993,MATCH(A6&"ENTRADA",Movimientos!$S$2:$S$1993,0)),"-")) -> L | F6: =IF(A6="","",COUNTIFS(Stock_por_Lote!$B:$B,A6,Stock_por_Lote!$J:$J,">0")) -> 1 | G6: =IF(A6="","",SUMIFS(Movimientos!$K:$K,Movimientos!$C:$C,A6)) -> 70 | H6: =IF(A6="","",IFERROR(IF(_xlfn.MINIFS(Stock_por_Lote!$H:$H,Stock_por_Lote!$B:$B,A6,Stock_por_Lote!$J:$J,">0")=0,"S/D",_xlfn.MINIFS(Stock_por_Lote!$H:$H,Stock_por_Lote!$B:$B,A6,Stock_por_Lote!$J:$J,">0")),"S/D")) -> 46517
A7: Tronador | B7: =IF(A7="","",IFERROR(INDEX(Movimientos!$D$2:$D$1993,MATCH(A7&"ENTRADA",Movimientos!$S$2:$S$1993,0)),"-")) -> Halauxifen metil 3.3% + Aminopyralid 2.7% + Metsulfuron metil 20% | C7: =IF(A7="","",IFERROR(INDEX(Movimientos!$E$2:$E$1993,MATCH(A7&"ENTRADA",Movimientos!$S$2:$S$1993,0)),"-")) -> Herbicida | D7: =IF(A7="","",IFERROR(INDEX(Movimientos!$F$2:$F$1993,MATCH(A7&"ENTRADA",Movimientos!$S$2:$S$1993,0)),"-")) -> Postemergente | E7: =IF(A7="","",IFERROR(INDEX(Movimientos!$L$2:$L$1993,MATCH(A7&"ENTRADA",Movimientos!$S$2:$S$1993,0)),"-")) -> Pack | F7: =IF(A7="","",COUNTIFS(Stock_por_Lote!$B:$B,A7,Stock_por_Lote!$J:$J,">0")) -> 0 | G7: =IF(A7="","",SUMIFS(Movimientos!$K:$K,Movimientos!$C:$C,A7)) -> 0 | H7: =IF(A7="","",IFERROR(IF(_xlfn.MINIFS(Stock_por_Lote!$H:$H,Stock_por_Lote!$B:$B,A7,Stock_por_Lote!$J:$J,">0")=0,"S/D",_xlfn.MINIFS(Stock_por_Lote!$H:$H,Stock_por_Lote!$B:$B,A7,Stock_por_Lote!$J:$J,">0")),"S/D")) -> S/D
A8: Venceweed extra | B8: =IF(A8="","",IFERROR(INDEX(Movimientos!$D$2:$D$1993,MATCH(A8&"ENTRADA",Movimientos!$S$2:$S$1993,0)),"-")) -> 2,4-Db-Butilo 93.1% | C8: =IF(A8="","",IFERROR(INDEX(Movimientos!$E$2:$E$1993,MATCH(A8&"ENTRADA",Movimientos!$S$2:$S$1993,0)),"-")) -> Herbicida | D8: =IF(A8="","",IFERROR(INDEX(Movimientos!$F$2:$F$1993,MATCH(A8&"ENTRADA",Movimientos!$S$2:$S$1993,0)),"-")) -> Postemergente | E8: =IF(A8="","",IFERROR(INDEX(Movimientos!$L$2:$L$1993,MATCH(A8&"ENTRADA",Movimientos!$S$2:$S$1993,0)),"-")) -> L | F8: =IF(A8="","",COUNTIFS(Stock_por_Lote!$B:$B,A8,Stock_por_Lote!$J:$J,">0")) -> 1 | G8: =IF(A8="","",SUMIFS(Movimientos!$K:$K,Movimientos!$C:$C,A8)) -> 1700 | H8: =IF(A8="","",IFERROR(IF(_xlfn.MINIFS(Stock_por_Lote!$H:$H,Stock_por_Lote!$B:$B,A8,Stock_por_Lote!$J:$J,">0")=0,"S/D",_xlfn.MINIFS(Stock_por_Lote!$H:$H,Stock_por_Lote!$B:$B,A8,Stock_por_Lote!$J:$J,">0")),"S/D")) -> 46737
A9: Dedalo elite | B9: =IF(A9="","",IFERROR(INDEX(Movimientos!$D$2:$D$1993,MATCH(A9&"ENTRADA",Movimientos!$S$2:$S$1993,0)),"-")) -> 2,4 D Acido 27.2% | C9: =IF(A9="","",IFERROR(INDEX(Movimientos!$E$2:$E$1993,MATCH(A9&"ENTRADA",Movimientos!$S$2:$S$1993,0)),"-")) -> Herbicida | D9: =IF(A9="","",IFERROR(INDEX(Movimientos!$F$2:$F$1993,MATCH(A9&"ENTRADA",Movimientos!$S$2:$S$1993,0)),"-")) -> Postemergente | E9: =IF(A9="","",IFERROR(INDEX(Movimientos!$L$2:$L$1993,MATCH(A9&"ENTRADA",Movimientos!$S$2:$S$1993,0)),"-")) -> L | F9: =IF(A9="","",COUNTIFS(Stock_por_Lote!$B:$B,A9,Stock_por_Lote!$J:$J,">0")) -> 1 | G9: =IF(A9="","",SUMIFS(Movimientos!$K:$K,Movimientos!$C:$C,A9)) -> 5960 | H9: =IF(A9="","",IFERROR(IF(_xlfn.MINIFS(Stock_por_Lote!$H:$H,Stock_por_Lote!$B:$B,A9,Stock_por_Lote!$J:$J,">0")=0,"S/D",_xlfn.MINIFS(Stock_por_Lote!$H:$H,Stock_por_Lote!$B:$B,A9,Stock_por_Lote!$J:$J,">0")),"S/D")) -> 46725
A10: Silobolsa | B10: =IF(A10="","",IFERROR(INDEX(Movimientos!$D$2:$D$1993,MATCH(A10&"ENTRADA",Movimientos!$S$2:$S$1993,0)),"-")) -> Silobolsa 9 pies | C10: =IF(A10="","",IFERROR(INDEX(Movimientos!$E$2:$E$1993,MATCH(A10&"ENTRADA",Movimientos!$S$2:$S$1993,0)),"-")) -> Silobolsa | D10: =IF(A10="","",IFERROR(INDEX(Movimientos!$F$2:$F$1993,MATCH(A10&"ENTRADA",Movimientos!$S$2:$S$1993,0)),"-")) -> 0 | E10: =IF(A10="","",IFERROR(INDEX(Movimientos!$L$2:$L$1993,MATCH(A10&"ENTRADA",Movimientos!$S$2:$S$1993,0)),"-")) -> unidad | F10: =IF(A10="","",COUNTIFS(Stock_por_Lote!$B:$B,A10,Stock_por_Lote!$J:$J,">0")) -> 0 | G10: =IF(A10="","",SUMIFS(Movimientos!$K:$K,Movimientos!$C:$C,A10)) -> 0 | H10: =IF(A10="","",IFERROR(IF(_xlfn.MINIFS(Stock_por_Lote!$H:$H,Stock_por_Lote!$B:$B,A10,Stock_por_Lote!$J:$J,">0")=0,"S/D",_xlfn.MINIFS(Stock_por_Lote!$H:$H,Stock_por_Lote!$B:$B,A10,Stock_por_Lote!$J:$J,">0")),"S/D")) -> S/D
A11: Raigrás E284 | B11: =IF(A11="","",IFERROR(INDEX(Movimientos!$D$2:$D$1993,MATCH(A11&"ENTRADA",Movimientos!$S$2:$S$1993,0)),"-")) -> Estanzuela 284 | C11: =IF(A11="","",IFERROR(INDEX(Movimientos!$E$2:$E$1993,MATCH(A11&"ENTRADA",Movimientos!$S$2:$S$1993,0)),"-")) -> Semilla | D11: =IF(A11="","",IFERROR(INDEX(Movimientos!$F$2:$F$1993,MATCH(A11&"ENTRADA",Movimientos!$S$2:$S$1993,0)),"-")) -> Raigrás | E11: =IF(A11="","",IFERROR(INDEX(Movimientos!$L$2:$L$1993,MATCH(A11&"ENTRADA",Movimientos!$S$2:$S$1993,0)),"-")) -> kg | F11: =IF(A11="","",COUNTIFS(Stock_por_Lote!$B:$B,A11,Stock_por_Lote!$J:$J,">0")) -> 0 | G11: =IF(A11="","",SUMIFS(Movimientos!$K:$K,Movimientos!$C:$C,A11)) -> 0 | H11: =IF(A11="","",IFERROR(IF(_xlfn.MINIFS(Stock_por_Lote!$H:$H,Stock_por_Lote!$B:$B,A11,Stock_por_Lote!$J:$J,">0")=0,"S/D",_xlfn.MINIFS(Stock_por_Lote!$H:$H,Stock_por_Lote!$B:$B,A11,Stock_por_Lote!$J:$J,">0")),"S/D")) -> S/D
A12: Starane Xtra | B12: =IF(A12="","",IFERROR(INDEX(Movimientos!$D$2:$D$1993,MATCH(A12&"ENTRADA",Movimientos!$S$2:$S$1993,0)),"-")) -> Fluroxypyr Meptil 45,52% | C12: =IF(A12="","",IFERROR(INDEX(Movimientos!$E$2:$E$1993,MATCH(A12&"ENTRADA",Movimientos!$S$2:$S$1993,0)),"-")) -> Herbicida | D12: =IF(A12="","",IFERROR(INDEX(Movimientos!$F$2:$F$1993,MATCH(A12&"ENTRADA",Movimientos!$S$2:$S$1993,0)),"-")) -> Postemergente | E12: =IF(A12="","",IFERROR(INDEX(Movimientos!$L$2:$L$1993,MATCH(A12&"ENTRADA",Movimientos!$S$2:$S$1993,0)),"-")) -> L | F12: =IF(A12="","",COUNTIFS(Stock_por_Lote!$B:$B,A12,Stock_por_Lote!$J:$J,">0")) -> 0 | G12: =IF(A12="","",SUMIFS(Movimientos!$K:$K,Movimientos!$C:$C,A12)) -> 0 | H12: =IF(A12="","",IFERROR(IF(_xlfn.MINIFS(Stock_por_Lote!$H:$H,Stock_por_Lote!$B:$B,A12,Stock_por_Lote!$J:$J,">0")=0,"S/D",_xlfn.MINIFS(Stock_por_Lote!$H:$H,Stock_por_Lote!$B:$B,A12,Stock_por_Lote!$J:$J,">0")),"S/D")) -> S/D
A13: Pixxaro | B13: =IF(A13="","",IFERROR(INDEX(Movimientos!$D$2:$D$1993,MATCH(A13&"ENTRADA",Movimientos!$S$2:$S$1993,0)),"-")) -> Fluroxypyr meptyl 34,91% + Halauxyfen methyl 1.64% + Cloquintocet mexyl 1.57% | C13: =IF(A13="","",IFERROR(INDEX(Movimientos!$E$2:$E$1993,MATCH(A13&"ENTRADA",Movimientos!$S$2:$S$1993,0)),"-")) -> Herbicida | D13: =IF(A13="","",IFERROR(INDEX(Movimientos!$F$2:$F$1993,MATCH(A13&"ENTRADA",Movimientos!$S$2:$S$1993,0)),"-")) -> Postemergente | E13: =IF(A13="","",IFERROR(INDEX(Movimientos!$L$2:$L$1993,MATCH(A13&"ENTRADA",Movimientos!$S$2:$S$1993,0)),"-")) -> L | F13: =IF(A13="","",COUNTIFS(Stock_por_Lote!$B:$B,A13,Stock_por_Lote!$J:$J,">0")) -> 1 | G13: =IF(A13="","",SUMIFS(Movimientos!$K:$K,Movimientos!$C:$C,A13)) -> 5460 | H13: =IF(A13="","",IFERROR(IF(_xlfn.MINIFS(Stock_por_Lote!$H:$H,Stock_por_Lote!$B:$B,A13,Stock_por_Lote!$J:$J,">0")=0,"S/D",_xlfn.MINIFS(Stock_por_Lote!$H:$H,Stock_por_Lote!$B:$B,A13,Stock_por_Lote!$J:$J,">0")),"S/D")) -> 46801
... A82: zinex | B82: =IF(A82="","",IFERROR(INDEX(Movimientos!$D$2:$D$1993,MATCH(A82&"ENTRADA",Movimientos!$S$2:$S$1993,0)),"-")) -> flumioxazim 480g/l | C82: =IF(A82="","",IFERROR(INDEX(Movimientos!$E$2:$E$1993,MATCH(A82&"ENTRADA",Movimientos!$S$2:$S$1993,0)),"-")) -> Herbicida | D82: =IF(A82="","",IFERROR(INDEX(Movimientos!$F$2:$F$1993,MATCH(A82&"ENTRADA",Movimientos!$S$2:$S$1993,0)),"-")) -> Preemergente | E82: =IF(A82="","",IFERROR(INDEX(Movimientos!$L$2:$L$1993,MATCH(A82&"ENTRADA",Movimientos!$S$2:$S$1993,0)),"-")) -> L | F82: =IF(A82="","",COUNTIFS(Stock_por_Lote!$B:$B,A82,Stock_por_Lote!$J:$J,">0")) -> 0 | G82: =IF(A82="","",SUMIFS(Movimientos!$K:$K,Movimientos!$C:$C,A82)) -> 1100 | H82: =IF(A82="","",IFERROR(IF(_xlfn.MINIFS(Stock_por_Lote!$H:$H,Stock_por_Lote!$B:$B,A82,Stock_por_Lote!$J:$J,">0")=0,"S/D",_xlfn.MINIFS(Stock_por_Lote!$H:$H,Stock_por_Lote!$B:$B,A82,Stock_por_Lote!$J:$J,">0")),"S/D")) -> S/D
B83: =IF(A83="","",IFERROR(INDEX(Movimientos!$D$2:$D$1993,MATCH(A83&"ENTRADA",Movimientos!$S$2:$S$1993,0)),"-")) | C83: =IF(A83="","",IFERROR(INDEX(Movimientos!$E$2:$E$1993,MATCH(A83&"ENTRADA",Movimientos!$S$2:$S$1993,0)),"-")) | D83: =IF(A83="","",IFERROR(INDEX(Movimientos!$F$2:$F$1993,MATCH(A83&"ENTRADA",Movimientos!$S$2:$S$1993,0)),"-")) | E83: =IF(A83="","",IFERROR(INDEX(Movimientos!$L$2:$L$1993,MATCH(A83&"ENTRADA",Movimientos!$S$2:$S$1993,0)),"-")) | F83: =IF(A83="","",COUNTIFS(Stock_por_Lote!$B:$B,A83,Stock_por_Lote!$J:$J,">0")) | G83: =IF(A83="","",SUMIFS(Movimientos!$K:$K,Movimientos!$C:$C,A83)) | H83: =IF(A83="","",IFERROR(IF(_xlfn.MINIFS(Stock_por_Lote!$H:$H,Stock_por_Lote!$B:$B,A83,Stock_por_Lote!$J:$J,">0")=0,"S/D",_xlfn.MINIFS(Stock_por_Lote!$H:$H,Stock_por_Lote!$B:$B,A83,Stock_por_Lote!$J:$J,">0")),"S/D"))
B84: =IF(A84="","",IFERROR(INDEX(Movimientos!$D$2:$D$1993,MATCH(A84&"ENTRADA",Movimientos!$S$2:$S$1993,0)),"-")) | C84: =IF(A84="","",IFERROR(INDEX(Movimientos!$E$2:$E$1993,MATCH(A84&"ENTRADA",Movimientos!$S$2:$S$1993,0)),"-")) | D84: =IF(A84="","",IFERROR(INDEX(Movimientos!$F$2:$F$1993,MATCH(A84&"ENTRADA",Movimientos!$S$2:$S$1993,0)),"-")) | E84: =IF(A84="","",IFERROR(INDEX(Movimientos!$L$2:$L$1993,MATCH(A84&"ENTRADA",Movimientos!$S$2:$S$1993,0)),"-")) | F84: =IF(A84="","",COUNTIFS(Stock_por_Lote!$B:$B,A84,Stock_por_Lote!$J:$J,">0")) | G84: =IF(A84="","",SUMIFS(Movimientos!$K:$K,Movimientos!$C:$C,A84)) | H84: =IF(A84="","",IFERROR(IF(_xlfn.MINIFS(Stock_por_Lote!$H:$H,Stock_por_Lote!$B:$B,A84,Stock_por_Lote!$J:$J,">0")=0,"S/D",_xlfn.MINIFS(Stock_por_Lote!$H:$H,Stock_por_Lote!$B:$B,A84,Stock_por_Lote!$J:$J,">0")),"S/D"))
B85: =IF(A85="","",IFERROR(INDEX(Movimientos!$D$2:$D$1993,MATCH(A85&"ENTRADA",Movimientos!$S$2:$S$1993,0)),"-")) | C85: =IF(A85="","",IFERROR(INDEX(Movimientos!$E$2:$E$1993,MATCH(A85&"ENTRADA",Movimientos!$S$2:$S$1993,0)),"-")) | D85: =IF(A85="","",IFERROR(INDEX(Movimientos!$F$2:$F$1993,MATCH(A85&"ENTRADA",Movimientos!$S$2:$S$1993,0)),"-")) | E85: =IF(A85="","",IFERROR(INDEX(Movimientos!$L$2:$L$1993,MATCH(A85&"ENTRADA",Movimientos!$S$2:$S$1993,0)),"-")) | F85: =IF(A85="","",COUNTIFS(Stock_por_Lote!$B:$B,A85,Stock_por_Lote!$J:$J,">0")) | G85: =IF(A85="","",SUMIFS(Movimientos!$K:$K,Movimientos!$C:$C,A85)) | H85: =IF(A85="","",IFERROR(IF(_xlfn.MINIFS(Stock_por_Lote!$H:$H,Stock_por_Lote!$B:$B,A85,Stock_por_Lote!$J:$J,">0")=0,"S/D",_xlfn.MINIFS(Stock_por_Lote!$H:$H,Stock_por_Lote!$B:$B,A85,Stock_por_Lote!$J:$J,">0")),"S/D"))
B86: =IF(A86="","",IFERROR(INDEX(Movimientos!$D$2:$D$1993,MATCH(A86&"ENTRADA",Movimientos!$S$2:$S$1993,0)),"-")) | C86: =IF(A86="","",IFERROR(INDEX(Movimientos!$E$2:$E$1993,MATCH(A86&"ENTRADA",Movimientos!$S$2:$S$1993,0)),"-")) | D86: =IF(A86="","",IFERROR(INDEX(Movimientos!$F$2:$F$1993,MATCH(A86&"ENTRADA",Movimientos!$S$2:$S$1993,0)),"-")) | E86: =IF(A86="","",IFERROR(INDEX(Movimientos!$L$2:$L$1993,MATCH(A86&"ENTRADA",Movimientos!$S$2:$S$1993,0)),"-")) | F86: =IF(A86="","",COUNTIFS(Stock_por_Lote!$B:$B,A86,Stock_por_Lote!$J:$J,">0")) | G86: =IF(A86="","",SUMIFS(Movimientos!$K:$K,Movimientos!$C:$C,A86)) | H86: =IF(A86="","",IFERROR(IF(_xlfn.MINIFS(Stock_por_Lote!$H:$H,Stock_por_Lote!$B:$B,A86,Stock_por_Lote!$J:$J,">0")=0,"S/D",_xlfn.MINIFS(Stock_por_Lote!$H:$H,Stock_por_Lote!$B:$B,A86,Stock_por_Lote!$J:$J,">0")),"S/D"))
B87: =IF(A87="","",IFERROR(INDEX(Movimientos!$D$2:$D$1993,MATCH(A87&"ENTRADA",Movimientos!$S$2:$S$1993,0)),"-")) | C87: =IF(A87="","",IFERROR(INDEX(Movimientos!$E$2:$E$1993,MATCH(A87&"ENTRADA",Movimientos!$S$2:$S$1993,0)),"-")) | D87: =IF(A87="","",IFERROR(INDEX(Movimientos!$F$2:$F$1993,MATCH(A87&"ENTRADA",Movimientos!$S$2:$S$1993,0)),"-")) | E87: =IF(A87="","",IFERROR(INDEX(Movimientos!$L$2:$L$1993,MATCH(A87&"ENTRADA",Movimientos!$S$2:$S$1993,0)),"-")) | F87: =IF(A87="","",COUNTIFS(Stock_por_Lote!$B:$B,A87,Stock_por_Lote!$J:$J,">0")) | G87: =IF(A87="","",SUMIFS(Movimientos!$K:$K,Movimientos!$C:$C,A87)) | H87: =IF(A87="","",IFERROR(IF(_xlfn.MINIFS(Stock_por_Lote!$H:$H,Stock_por_Lote!$B:$B,A87,Stock_por_Lote!$J:$J,">0")=0,"S/D",_xlfn.MINIFS(Stock_por_Lote!$H:$H,Stock_por_Lote!$B:$B,A87,Stock_por_Lote!$J:$J,">0")),"S/D"))
B88: =IF(A88="","",IFERROR(INDEX(Movimientos!$D$2:$D$1993,MATCH(A88&"ENTRADA",Movimientos!$S$2:$S$1993,0)),"-")) | C88: =IF(A88="","",IFERROR(INDEX(Movimientos!$E$2:$E$1993,MATCH(A88&"ENTRADA",Movimientos!$S$2:$S$1993,0)),"-")) | D88: =IF(A88="","",IFERROR(INDEX(Movimientos!$F$2:$F$1993,MATCH(A88&"ENTRADA",Movimientos!$S$2:$S$1993,0)),"-")) | E88: =IF(A88="","",IFERROR(INDEX(Movimientos!$L$2:$L$1993,MATCH(A88&"ENTRADA",Movimientos!$S$2:$S$1993,0)),"-")) | F88: =IF(A88="","",COUNTIFS(Stock_por_Lote!$B:$B,A88,Stock_por_Lote!$J:$J,">0")) | G88: =IF(A88="","",SUMIFS(Movimientos!$K:$K,Movimientos!$C:$C,A88)) | H88: =IF(A88="","",IFERROR(IF(_xlfn.MINIFS(Stock_por_Lote!$H:$H,Stock_por_Lote!$B:$B,A88,Stock_por_Lote!$J:$J,">0")=0,"S/D",_xlfn.MINIFS(Stock_por_Lote!$H:$H,Stock_por_Lote!$B:$B,A88,Stock_por_Lote!$J:$J,">0")),"S/D"))
B89: =IF(A89="","",IFERROR(INDEX(Movimientos!$D$2:$D$1993,MATCH(A89&"ENTRADA",Movimientos!$S$2:$S$1993,0)),"-")) | C89: =IF(A89="","",IFERROR(INDEX(Movimientos!$E$2:$E$1993,MATCH(A89&"ENTRADA",Movimientos!$S$2:$S$1993,0)),"-")) | D89: =IF(A89="","",IFERROR(INDEX(Movimientos!$F$2:$F$1993,MATCH(A89&"ENTRADA",Movimientos!$S$2:$S$1993,0)),"-")) | E89: =IF(A89="","",IFERROR(INDEX(Movimientos!$L$2:$L$1993,MATCH(A89&"ENTRADA",Movimientos!$S$2:$S$1993,0)),"-")) | F89: =IF(A89="","",COUNTIFS(Stock_por_Lote!$B:$B,A89,Stock_por_Lote!$J:$J,">0")) | G89: =IF(A89="","",SUMIFS(Movimientos!$K:$K,Movimientos!$C:$C,A89)) | H89: =IF(A89="","",IFERROR(IF(_xlfn.MINIFS(Stock_por_Lote!$H:$H,Stock_por_Lote!$B:$B,A89,Stock_por_Lote!$J:$J,">0")=0,"S/D",_xlfn.MINIFS(Stock_por_Lote!$H:$H,Stock_por_Lote!$B:$B,A89,Stock_por_Lote!$J:$J,">0")),"S/D"))
B90: =IF(A90="","",IFERROR(INDEX(Movimientos!$D$2:$D$1993,MATCH(A90&"ENTRADA",Movimientos!$S$2:$S$1993,0)),"-")) | C90: =IF(A90="","",IFERROR(INDEX(Movimientos!$E$2:$E$1993,MATCH(A90&"ENTRADA",Movimientos!$S$2:$S$1993,0)),"-")) | D90: =IF(A90="","",IFERROR(INDEX(Movimientos!$F$2:$F$1993,MATCH(A90&"ENTRADA",Movimientos!$S$2:$S$1993,0)),"-")) | E90: =IF(A90="","",IFERROR(INDEX(Movimientos!$L$2:$L$1993,MATCH(A90&"ENTRADA",Movimientos!$S$2:$S$1993,0)),"-")) | F90: =IF(A90="","",COUNTIFS(Stock_por_Lote!$B:$B,A90,Stock_por_Lote!$J:$J,">0")) | G90: =IF(A90="","",SUMIFS(Movimientos!$K:$K,Movimientos!$C:$C,A90)) | H90: =IF(A90="","",IFERROR(IF(_xlfn.MINIFS(Stock_por_Lote!$H:$H,Stock_por_Lote!$B:$B,A90,Stock_por_Lote!$J:$J,">0")=0,"S/D",_xlfn.MINIFS(Stock_por_Lote!$H:$H,Stock_por_Lote!$B:$B,A90,Stock_por_Lote!$J:$J,">0")),"S/D"))
B91: =IF(A91="","",IFERROR(INDEX(Movimientos!$D$2:$D$1993,MATCH(A91&"ENTRADA",Movimientos!$S$2:$S$1993,0)),"-")) | C91: =IF(A91="","",IFERROR(INDEX(Movimientos!$E$2:$E$1993,MATCH(A91&"ENTRADA",Movimientos!$S$2:$S$1993,0)),"-")) | D91: =IF(A91="","",IFERROR(INDEX(Movimientos!$F$2:$F$1993,MATCH(A91&"ENTRADA",Movimientos!$S$2:$S$1993,0)),"-")) | E91: =IF(A91="","",IFERROR(INDEX(Movimientos!$L$2:$L$1993,MATCH(A91&"ENTRADA",Movimientos!$S$2:$S$1993,0)),"-")) | F91: =IF(A91="","",COUNTIFS(Stock_por_Lote!$B:$B,A91,Stock_por_Lote!$J:$J,">0")) | G91: =IF(A91="","",SUMIFS(Movimientos!$K:$K,Movimientos!$C:$C,A91)) | H91: =IF(A91="","",IFERROR(IF(_xlfn.MINIFS(Stock_por_Lote!$H:$H,Stock_por_Lote!$B:$B,A91,Stock_por_Lote!$J:$J,">0")=0,"S/D",_xlfn.MINIFS(Stock_por_Lote!$H:$H,Stock_por_Lote!$B:$B,A91,Stock_por_Lote!$J:$J,">0")),"S/D"))
B92: =IF(A92="","",IFERROR(INDEX(Movimientos!$D$2:$D$1993,MATCH(A92&"ENTRADA",Movimientos!$S$2:$S$1993,0)),"-")) | C92: =IF(A92="","",IFERROR(INDEX(Movimientos!$E$2:$E$1993,MATCH(A92&"ENTRADA",Movimientos!$S$2:$S$1993,0)),"-")) | D92: =IF(A92="","",IFERROR(INDEX(Movimientos!$F$2:$F$1993,MATCH(A92&"ENTRADA",Movimientos!$S$2:$S$1993,0)),"-")) | E92: =IF(A92="","",IFERROR(INDEX(Movimientos!$L$2:$L$1993,MATCH(A92&"ENTRADA",Movimientos!$S$2:$S$1993,0)),"-")) | F92: =IF(A92="","",COUNTIFS(Stock_por_Lote!$B:$B,A92,Stock_por_Lote!$J:$J,">0")) | G92: =IF(A92="","",SUMIFS(Movimientos!$K:$K,Movimientos!$C:$C,A92)) | H92: =IF(A92="","",IFERROR(IF(_xlfn.MINIFS(Stock_por_Lote!$H:$H,Stock_por_Lote!$B:$B,A92,Stock_por_Lote!$J:$J,">0")=0,"S/D",_xlfn.MINIFS(Stock_por_Lote!$H:$H,Stock_por_Lote!$B:$B,A92,Stock_por_Lote!$J:$J,">0")),"S/D"))
B93: =IF(A93="","",IFERROR(INDEX(Movimientos!$D$2:$D$1993,MATCH(A93&"ENTRADA",Movimientos!$S$2:$S$1993,0)),"-")) | C93: =IF(A93="","",IFERROR(INDEX(Movimientos!$E$2:$E$1993,MATCH(A93&"ENTRADA",Movimientos!$S$2:$S$1993,0)),"-")) | D93: =IF(A93="","",IFERROR(INDEX(Movimientos!$F$2:$F$1993,MATCH(A93&"ENTRADA",Movimientos!$S$2:$S$1993,0)),"-")) | E93: =IF(A93="","",IFERROR(INDEX(Movimientos!$L$2:$L$1993,MATCH(A93&"ENTRADA",Movimientos!$S$2:$S$1993,0)),"-")) | F93: =IF(A93="","",COUNTIFS(Stock_por_Lote!$B:$B,A93,Stock_por_Lote!$J:$J,">0")) | G93: =IF(A93="","",SUMIFS(Movimientos!$K:$K,Movimientos!$C:$C,A93)) | H93: =IF(A93="","",IFERROR(IF(_xlfn.MINIFS(Stock_por_Lote!$H:$H,Stock_por_Lote!$B:$B,A93,Stock_por_Lote!$J:$J,">0")=0,"S/D",_xlfn.MINIFS(Stock_por_Lote!$H:$H,Stock_por_Lote!$B:$B,A93,Stock_por_Lote!$J:$J,">0")),"S/D"))
B94: =IF(A94="","",IFERROR(INDEX(Movimientos!$D$2:$D$1993,MATCH(A94&"ENTRADA",Movimientos!$S$2:$S$1993,0)),"-")) | C94: =IF(A94="","",IFERROR(INDEX(Movimientos!$E$2:$E$1993,MATCH(A94&"ENTRADA",Movimientos!$S$2:$S$1993,0)),"-")) | D94: =IF(A94="","",IFERROR(INDEX(Movimientos!$F$2:$F$1993,MATCH(A94&"ENTRADA",Movimientos!$S$2:$S$1993,0)),"-")) | E94: =IF(A94="","",IFERROR(INDEX(Movimientos!$L$2:$L$1993,MATCH(A94&"ENTRADA",Movimientos!$S$2:$S$1993,0)),"-")) | F94: =IF(A94="","",COUNTIFS(Stock_por_Lote!$B:$B,A94,Stock_por_Lote!$J:$J,">0")) | G94: =IF(A94="","",SUMIFS(Movimientos!$K:$K,Movimientos!$C:$C,A94)) | H94: =IF(A94="","",IFERROR(IF(_xlfn.MINIFS(Stock_por_Lote!$H:$H,Stock_por_Lote!$B:$B,A94,Stock_por_Lote!$J:$J,">0")=0,"S/D",_xlfn.MINIFS(Stock_por_Lote!$H:$H,Stock_por_Lote!$B:$B,A94,Stock_por_Lote!$J:$J,">0")),"S/D"))
... B112: =IF(A112="","",IFERROR(INDEX(Movimientos!$D$2:$D$1993,MATCH(A112&"ENTRADA",Movimientos!$S$2:$S$1993,0)),"-")) | C112: =IF(A112="","",IFERROR(INDEX(Movimientos!$E$2:$E$1993,MATCH(A112&"ENTRADA",Movimientos!$S$2:$S$1993,0)),"-")) | D112: =IF(A112="","",IFERROR(INDEX(Movimientos!$F$2:$F$1993,MATCH(A112&"ENTRADA",Movimientos!$S$2:$S$1993,0)),"-")) | E112: =IF(A112="","",IFERROR(INDEX(Movimientos!$L$2:$L$1993,MATCH(A112&"ENTRADA",Movimientos!$S$2:$S$1993,0)),"-")) | F112: =IF(A112="","",COUNTIFS(Stock_por_Lote!$B:$B,A112,Stock_por_Lote!$J:$J,">0")) | G112: =IF(A112="","",SUMIFS(Movimientos!$K:$K,Movimientos!$C:$C,A112)) | H112: =IF(A112="","",IFERROR(IF(_xlfn.MINIFS(Stock_por_Lote!$H:$H,Stock_por_Lote!$B:$B,A112,Stock_por_Lote!$J:$J,">0")=0,"S/D",_xlfn.MINIFS(Stock_por_Lote!$H:$H,Stock_por_Lote!$B:$B,A112,Stock_por_Lote!$J:$J,">0")),"S/D"))

Sheet Stock_por_Lote
A1: ID_Lote (escribir aquí) | B1: Producto | C1: Principio Activo/Variedad | D1: Tipo | E1: Subtipo | F1: Proveedor | G1: Unidad | H1: Vencimiento | I1: Días a vencimiento | J1: Stock Actual | K1: Estado
A2: 260324-001 | B2: =IFERROR(INDEX(Movimientos!$C$2:$C$1993,MATCH(A2&"ENTRADA",Movimientos!$R$2:$R$1993,0)),"-") -> Colza Curry CL | C2: =IFERROR(INDEX(Movimientos!$D$2:$D$1993,MATCH(A2&"ENTRADA",Movimientos!$R$2:$R$1993,0)),"-") -> CURRY CL | D2: =IFERROR(INDEX(Movimientos!$E$2:$E$1993,MATCH(A2&"ENTRADA",Movimientos!$R$2:$R$1993,0)),"-") -> Semilla | E2: =IFERROR(INDEX(Movimientos!$F$2:$F$1993,MATCH(A2&"ENTRADA",Movimientos!$R$2:$R$1993,0)),"-") -> Colza | F2: =IFERROR(INDEX(Movimientos!$G$2:$G$1993,MATCH(A2&"ENTRADA",Movimientos!$R$2:$R$1993,0)),"-") -> ERRO | G2: =IFERROR(INDEX(Movimientos!$L$2:$L$1993,MATCH(A2&"ENTRADA",Movimientos!$R$2:$R$1993,0)),"-") -> kg | H2: =IFERROR(IF(INDEX(Movimientos!$M$2:$M$1993,MATCH(A2&"ENTRADA",Movimientos!$R$2:$R$1993,0))=0,"S/D",INDEX(Movimientos!$M$2:$M$1993,MATCH(A2&"ENTRADA",Movimientos!$R$2:$R$1993,0))),"S/D") -> S/D | I2: =IF(OR(A2="",H2="S/D"),"S/D",H2-TODAY()) -> S/D | J2: =IF(A2="","",SUMIFS(Movimientos!$K:$K,Movimientos!$H:$H,A2)) -> 0 | K2: =IF(A2="","",IF(J2<0.01,"SIN STOCK",IF(H2="S/D","OK",IF(H2<TODAY(),"VENCIDO",IF(I2>=180,"OK","PRÓXIMO A VENCER"))))) -> SIN STOCK
A3: 260401-002 | B3: =IFERROR(INDEX(Movimientos!$C$2:$C$1993,MATCH(A3&"ENTRADA",Movimientos!$R$2:$R$1993,0)),"-") -> Korvetto | C3: =IFERROR(INDEX(Movimientos!$D$2:$D$1993,MATCH(A3&"ENTRADA",Movimientos!$R$2:$R$1993,0)),"-") -> Clopyralid 12% + Halauxyfen methyl 0,51% | D3: =IFERROR(INDEX(Movimientos!$E$2:$E$1993,MATCH(A3&"ENTRADA",Movimientos!$R$2:$R$1993,0)),"-") -> Herbicida | E3: =IFERROR(INDEX(Movimientos!$F$2:$F$1993,MATCH(A3&"ENTRADA",Movimientos!$R$2:$R$1993,0)),"-") -> Postemergente | F3: =IFERROR(INDEX(Movimientos!$G$2:$G$1993,MATCH(A3&"ENTRADA",Movimientos!$R$2:$R$1993,0)),"-") -> GS Agro | G3: =IFERROR(INDEX(Movimientos!$L$2:$L$1993,MATCH(A3&"ENTRADA",Movimientos!$R$2:$R$1993,0)),"-") -> L | H3: =IFERROR(IF(INDEX(Movimientos!$M$2:$M$1993,MATCH(A3&"ENTRADA",Movimientos!$R$2:$R$1993,0))=0,"S/D",INDEX(Movimientos!$M$2:$M$1993,MATCH(A3&"ENTRADA",Movimientos!$R$2:$R$1993,0))),"S/D") -> 46710 | I3: =IF(OR(A3="",H3="S/D"),"S/D",H3-TODAY()) -> 401 | J3: =IF(A3="","",SUMIFS(Movimientos!$K:$K,Movimientos!$H:$H,A3)) -> 10 | K3: =IF(A3="","",IF(J3<0.01,"SIN STOCK",IF(H3="S/D","OK",IF(H3<TODAY(),"VENCIDO",IF(I3>=180,"OK","PRÓXIMO A VENCER"))))) -> OK
A4: 260401-003 | B4: =IFERROR(INDEX(Movimientos!$C$2:$C$1993,MATCH(A4&"ENTRADA",Movimientos!$R$2:$R$1993,0)),"-") -> Lontrel | C4: =IFERROR(INDEX(Movimientos!$D$2:$D$1993,MATCH(A4&"ENTRADA",Movimientos!$R$2:$R$1993,0)),"-") -> Clopyralid sal monoetanolamina 40.9% | D4: =IFERROR(INDEX(Movimientos!$E$2:$E$1993,MATCH(A4&"ENTRADA",Movimientos!$R$2:$R$1993,0)),"-") -> Herbicida | E4: =IFERROR(INDEX(Movimientos!$F$2:$F$1993,MATCH(A4&"ENTRADA",Movimientos!$R$2:$R$1993,0)),"-") -> Postemergente | F4: =IFERROR(INDEX(Movimientos!$G$2:$G$1993,MATCH(A4&"ENTRADA",Movimientos!$R$2:$R$1993,0)),"-") -> GS Agro | G4: =IFERROR(INDEX(Movimientos!$L$2:$L$1993,MATCH(A4&"ENTRADA",Movimientos!$R$2:$R$1993,0)),"-") -> L | H4: =IFERROR(IF(INDEX(Movimientos!$M$2:$M$1993,MATCH(A4&"ENTRADA",Movimientos!$R$2:$R$1993,0))=0,"S/D",INDEX(Movimientos!$M$2:$M$1993,MATCH(A4&"ENTRADA",Movimientos!$R$2:$R$1993,0))),"S/D") -> 46500 | I4: =IF(OR(A4="",H4="S/D"),"S/D",H4-TODAY()) -> 191 | J4: =IF(A4="","",SUMIFS(Movimientos!$K:$K,Movimientos!$H:$H,A4)) -> 255 | K4: =IF(A4="","",IF(J4<0.01,"SIN STOCK",IF(H4="S/D","OK",IF(H4<TODAY(),"VENCIDO",IF(I4>=180,"OK","PRÓXIMO A VENCER"))))) -> OK
A5: 260401-004 | B5: =IFERROR(INDEX(Movimientos!$C$2:$C$1993,MATCH(A5&"ENTRADA",Movimientos!$R$2:$R$1993,0)),"-") -> Preside | C5: =IFERROR(INDEX(Movimientos!$D$2:$D$1993,MATCH(A5&"ENTRADA",Movimientos!$R$2:$R$1993,0)),"-") -> Flumetsulam 11,35% | D5: =IFERROR(INDEX(Movimientos!$E$2:$E$1993,MATCH(A5&"ENTRADA",Movimientos!$R$2:$R$1993,0)),"-") -> Herbicida | E5: =IFERROR(INDEX(Movimientos!$F$2:$F$1993,MATCH(A5&"ENTRADA",Movimientos!$R$2:$R$1993,0)),"-") -> Preemergente | F5: =IFERROR(INDEX(Movimientos!$G$2:$G$1993,MATCH(A5&"ENTRADA",Movimientos!$R$2:$R$1993,0)),"-") -> GS Agro | G5: =IFERROR(INDEX(Movimientos!$L$2:$L$1993,MATCH(A5&"ENTRADA",Movimientos!$R$2:$R$1993,0)),"-") -> L | H5: =IFERROR(IF(INDEX(Movimientos!$M$2:$M$1993,MATCH(A5&"ENTRADA",Movimientos!$R$2:$R$1993,0))=0,"S/D",INDEX(Movimientos!$M$2:$M$1993,MATCH(A5&"ENTRADA",Movimientos!$R$2:$R$1993,0))),"S/D") -> 46528 | I5: =IF(OR(A5="",H5="S/D"),"S/D",H5-TODAY()) -> 219 | J5: =IF(A5="","",SUMIFS(Movimientos!$K:$K,Movimientos!$H:$H,A5)) -> 1820 | K5: =IF(A5="","",IF(J5<0.01,"SIN STOCK",IF(H5="S/D","OK",IF(H5<TODAY(),"VENCIDO",IF(I5>=180,"OK","PRÓXIMO A VENCER"))))) -> OK
A6: 260401-005 | B6: =IFERROR(INDEX(Movimientos!$C$2:$C$1993,MATCH(A6&"ENTRADA",Movimientos!$R$2:$R$1993,0)),"-") -> Preside | C6: =IFERROR(INDEX(Movimientos!$D$2:$D$1993,MATCH(A6&"ENTRADA",Movimientos!$R$2:$R$1993,0)),"-") -> Flumetsulam 11,35% | D6: =IFERROR(INDEX(Movimientos!$E$2:$E$1993,MATCH(A6&"ENTRADA",Movimientos!$R$2:$R$1993,0)),"-") -> Herbicida | E6: =IFERROR(INDEX(Movimientos!$F$2:$F$1993,MATCH(A6&"ENTRADA",Movimientos!$R$2:$R$1993,0)),"-") -> Preemergente | F6: =IFERROR(INDEX(Movimientos!$G$2:$G$1993,MATCH(A6&"ENTRADA",Movimientos!$R$2:$R$1993,0)),"-") -> GS Agro | G6: =IFERROR(INDEX(Movimientos!$L$2:$L$1993,MATCH(A6&"ENTRADA",Movimientos!$R$2:$R$1993,0)),"-") -> L | H6: =IFERROR(IF(INDEX(Movimientos!$M$2:$M$1993,MATCH(A6&"ENTRADA",Movimientos!$R$2:$R$1993,0))=0,"S/D",INDEX(Movimientos!$M$2:$M$1993,MATCH(A6&"ENTRADA",Movimientos!$R$2:$R$1993,0))),"S/D") -> 46761 | I6: =IF(OR(A6="",H6="S/D"),"S/D",H6-TODAY()) -> 452 | J6: =IF(A6="","",SUMIFS(Movimientos!$K:$K,Movimientos!$H:$H,A6)) -> 100 | K6: =IF(A6="","",IF(J6<0.01,"SIN STOCK",IF(H6="S/D","OK",IF(H6<TODAY(),"VENCIDO",IF(I6>=180,"OK","PRÓXIMO A VENCER"))))) -> OK
A7: 260401-006 | B7: =IFERROR(INDEX(Movimientos!$C$2:$C$1993,MATCH(A7&"ENTRADA",Movimientos!$R$2:$R$1993,0)),"-") -> Tordon 24K | C7: =IFERROR(INDEX(Movimientos!$D$2:$D$1993,MATCH(A7&"ENTRADA",Movimientos!$R$2:$R$1993,0)),"-") -> Picloram 24,9% | D7: =IFERROR(INDEX(Movimientos!$E$2:$E$1993,MATCH(A7&"ENTRADA",Movimientos!$R$2:$R$1993,0)),"-") -> Herbicida | E7: =IFERROR(INDEX(Movimientos!$F$2:$F$1993,MATCH(A7&"ENTRADA",Movimientos!$R$2:$R$1993,0)),"-") -> Postemergente | F7: =IFERROR(INDEX(Movimientos!$G$2:$G$1993,MATCH(A7&"ENTRADA",Movimientos!$R$2:$R$1993,0)),"-") -> GS Agro | G7: =IFERROR(INDEX(Movimientos!$L$2:$L$1993,MATCH(A7&"ENTRADA",Movimientos!$R$2:$R$1993,0)),"-") -> L | H7: =IFERROR(IF(INDEX(Movimientos!$M$2:$M$1993,MATCH(A7&"ENTRADA",Movimientos!$R$2:$R$1993,0))=0,"S/D",INDEX(Movimientos!$M$2:$M$1993,MATCH(A7&"ENTRADA",Movimientos!$R$2:$R$1993,0))),"S/D") -> 46517 | I7: =IF(OR(A7="",H7="S/D"),"S/D",H7-TODAY()) -> 208 | J7: =IF(A7="","",SUMIFS(Movimientos!$K:$K,Movimientos!$H:$H,A7)) -> 70 | K7: =IF(A7="","",IF(J7<0.01,"SIN STOCK",IF(H7="S/D","OK",IF(H7<TODAY(),"VENCIDO",IF(I7>=180,"OK","PRÓXIMO A VENCER"))))) -> OK
A8: 260401-007 | B8: =IFERROR(INDEX(Movimientos!$C$2:$C$1993,MATCH(A8&"ENTRADA",Movimientos!$R$2:$R$1993,0)),"-") -> Tronador | C8: =IFERROR(INDEX(Movimientos!$D$2:$D$1993,MATCH(A8&"ENTRADA",Movimientos!$R$2:$R$1993,0)),"-") -> Halauxifen metil 3.3% + Aminopyralid 2.7% + Metsulfuron metil 20% | D8: =IFERROR(INDEX(Movimientos!$E$2:$E$1993,MATCH(A8&"ENTRADA",Movimientos!$R$2:$R$1993,0)),"-") -> Herbicida | E8: =IFERROR(INDEX(Movimientos!$F$2:$F$1993,MATCH(A8&"ENTRADA",Movimientos!$R$2:$R$1993,0)),"-") -> Postemergente | F8: =IFERROR(INDEX(Movimientos!$G$2:$G$1993,MATCH(A8&"ENTRADA",Movimientos!$R$2:$R$1993,0)),"-") -> GS Agro | G8: =IFERROR(INDEX(Movimientos!$L$2:$L$1993,MATCH(A8&"ENTRADA",Movimientos!$R$2:$R$1993,0)),"-") -> Pack | H8: =IFERROR(IF(INDEX(Movimientos!$M$2:$M$1993,MATCH(A8&"ENTRADA",Movimientos!$R$2:$R$1993,0))=0,"S/D",INDEX(Movimientos!$M$2:$M$1993,MATCH(A8&"ENTRADA",Movimientos!$R$2:$R$1993,0))),"S/D") -> 46443 | I8: =IF(OR(A8="",H8="S/D"),"S/D",H8-TODAY()) -> 134 | J8: =IF(A8="","",SUMIFS(Movimientos!$K:$K,Movimientos!$H:$H,A8)) -> 0 | K8: =IF(A8="","",IF(J8<0.01,"SIN STOCK",IF(H8="S/D","OK",IF(H8<TODAY(),"VENCIDO",IF(I8>=180,"OK","PRÓXIMO A VENCER"))))) -> SIN STOCK
A9: 260401-008 | B9: =IFERROR(INDEX(Movimientos!$C$2:$C$1993,MATCH(A9&"ENTRADA",Movimientos!$R$2:$R$1993,0)),"-") -> Venceweed extra | C9: =IFERROR(INDEX(Movimientos!$D$2:$D$1993,MATCH(A9&"ENTRADA",Movimientos!$R$2:$R$1993,0)),"-") -> 2,4-Db-Butilo 93.1% | D9: =IFERROR(INDEX(Movimientos!$E$2:$E$1993,MATCH(A9&"ENTRADA",Movimientos!$R$2:$R$1993,0)),"-") -> Herbicida | E9: =IFERROR(INDEX(Movimientos!$F$2:$F$1993,MATCH(A9&"ENTRADA",Movimientos!$R$2:$R$1993,0)),"-") -> Postemergente | F9: =IFERROR(INDEX(Movimientos!$G$2:$G$1993,MATCH(A9&"ENTRADA",Movimientos!$R$2:$R$1993,0)),"-") -> GS Agro | G9: =IFERROR(INDEX(Movimientos!$L$2:$L$1993,MATCH(A9&"ENTRADA",Movimientos!$R$2:$R$1993,0)),"-") -> L | H9: =IFERROR(IF(INDEX(Movimientos!$M$2:$M$1993,MATCH(A9&"ENTRADA",Movimientos!$R$2:$R$1993,0))=0,"S/D",INDEX(Movimientos!$M$2:$M$1993,MATCH(A9&"ENTRADA",Movimientos!$R$2:$R$1993,0))),"S/D") -> 46737 | I9: =IF(OR(A9="",H9="S/D"),"S/D",H9-TODAY()) -> 428 | J9: =IF(A9="","",SUMIFS(Movimientos!$K:$K,Movimientos!$H:$H,A9)) -> 1700 | K9: =IF(A9="","",IF(J9<0.01,"SIN STOCK",IF(H9="S/D","OK",IF(H9<TODAY(),"VENCIDO",IF(I9>=180,"OK","PRÓXIMO A VENCER"))))) -> OK
A10: 260406-011 | B10: =IFERROR(INDEX(Movimientos!$C$2:$C$1993,MATCH(A10&"ENTRADA",Movimientos!$R$2:$R$1993,0)),"-") -> Silobolsa | C10: =IFERROR(INDEX(Movimientos!$D$2:$D$1993,MATCH(A10&"ENTRADA",Movimientos!$R$2:$R$1993,0)),"-") -> Silobolsa 9 pies | D10: =IFERROR(INDEX(Movimientos!$E$2:$E$1993,MATCH(A10&"ENTRADA",Movimientos!$R$2:$R$1993,0)),"-") -> Silobolsa | E10: =IFERROR(INDEX(Movimientos!$F$2:$F$1993,MATCH(A10&"ENTRADA",Movimientos!$R$2:$R$1993,0)),"-") -> 0 | F10: =IFERROR(INDEX(Movimientos!$G$2:$G$1993,MATCH(A10&"ENTRADA",Movimientos!$R$2:$R$1993,0)),"-") -> AYP Agrogestiones | G10: =IFERROR(INDEX(Movimientos!$L$2:$L$1993,MATCH(A10&"ENTRADA",Movimientos!$R$2:$R$1993,0)),"-") -> unidad | H10: =IFERROR(IF(INDEX(Movimientos!$M$2:$M$1993,MATCH(A10&"ENTRADA",Movimientos!$R$2:$R$1993,0))=0,"S/D",INDEX(Movimientos!$M$2:$M$1993,MATCH(A10&"ENTRADA",Movimientos!$R$2:$R$1993,0))),"S/D") -> S/D | I10: =IF(OR(A10="",H10="S/D"),"S/D",H10-TODAY()) -> S/D | J10: =IF(A10="","",SUMIFS(Movimientos!$K:$K,Movimientos!$H:$H,A10)) -> 0 | K10: =IF(A10="","",IF(J10<0.01,"SIN STOCK",IF(H10="S/D","OK",IF(H10<TODAY(),"VENCIDO",IF(I10>=180,"OK","PRÓXIMO A VENCER"))))) -> SIN STOCK
A11: 260407-012 | B11: =IFERROR(INDEX(Movimientos!$C$2:$C$1993,MATCH(A11&"ENTRADA",Movimientos!$R$2:$R$1993,0)),"-") -> Dedalo elite | C11: =IFERROR(INDEX(Movimientos!$D$2:$D$1993,MATCH(A11&"ENTRADA",Movimientos!$R$2:$R$1993,0)),"-") -> 2,4 D Acido 27.2% | D11: =IFERROR(INDEX(Movimientos!$E$2:$E$1993,MATCH(A11&"ENTRADA",Movimientos!$R$2:$R$1993,0)),"-") -> Herbicida | E11: =IFERROR(INDEX(Movimientos!$F$2:$F$1993,MATCH(A11&"ENTRADA",Movimientos!$R$2:$R$1993,0)),"-") -> Postemergente | F11: =IFERROR(INDEX(Movimientos!$G$2:$G$1993,MATCH(A11&"ENTRADA",Movimientos!$R$2:$R$1993,0)),"-") -> Agromil | G11: =IFERROR(INDEX(Movimientos!$L$2:$L$1993,MATCH(A11&"ENTRADA",Movimientos!$R$2:$R$1993,0)),"-") -> L | H11: =IFERROR(IF(INDEX(Movimientos!$M$2:$M$1993,MATCH(A11&"ENTRADA",Movimientos!$R$2:$R$1993,0))=0,"S/D",INDEX(Movimientos!$M$2:$M$1993,MATCH(A11&"ENTRADA",Movimientos!$R$2:$R$1993,0))),"S/D") -> 46725 | I11: =IF(OR(A11="",H11="S/D"),"S/D",H11-TODAY()) -> 416 | J11: =IF(A11="","",SUMIFS(Movimientos!$K:$K,Movimientos!$H:$H,A11)) -> 5960 | K11: =IF(A11="","",IF(J11<0.01,"SIN STOCK",IF(H11="S/D","OK",IF(H11<TODAY(),"VENCIDO",IF(I11>=180,"OK","PRÓXIMO A VENCER"))))) -> OK
A12: 260408-013 | B12: =IFERROR(INDEX(Movimientos!$C$2:$C$1993,MATCH(A12&"ENTRADA",Movimientos!$R$2:$R$1993,0)),"-") -> Raigrás E284 | C12: =IFERROR(INDEX(Movimientos!$D$2:$D$1993,MATCH(A12&"ENTRADA",Movimientos!$R$2:$R$1993,0)),"-") -> Estanzuela 284 | D12: =IFERROR(INDEX(Movimientos!$E$2:$E$1993,MATCH(A12&"ENTRADA",Movimientos!$R$2:$R$1993,0)),"-") -> Semilla | E12: =IFERROR(INDEX(Movimientos!$F$2:$F$1993,MATCH(A12&"ENTRADA",Movimientos!$R$2:$R$1993,0)),"-") -> Raigrás | F12: =IFERROR(INDEX(Movimientos!$G$2:$G$1993,MATCH(A12&"ENTRADA",Movimientos!$R$2:$R$1993,0)),"-") -> Granicor | G12: =IFERROR(INDEX(Movimientos!$L$2:$L$1993,MATCH(A12&"ENTRADA",Movimientos!$R$2:$R$1993,0)),"-") -> kg | H12: =IFERROR(IF(INDEX(Movimientos!$M$2:$M$1993,MATCH(A12&"ENTRADA",Movimientos!$R$2:$R$1993,0))=0,"S/D",INDEX(Movimientos!$M$2:$M$1993,MATCH(A12&"ENTRADA",Movimientos!$R$2:$R$1993,0))),"S/D") -> S/D | I12: =IF(OR(A12="",H12="S/D"),"S/D",H12-TODAY()) -> S/D | J12: =IF(A12="","",SUMIFS(Movimientos!$K:$K,Movimientos!$H:$H,A12)) -> 0 | K12: =IF(A12="","",IF(J12<0.01,"SIN STOCK",IF(H12="S/D","OK",IF(H12<TODAY(),"VENCIDO",IF(I12>=180,"OK","PRÓXIMO A VENCER"))))) -> SIN STOCK
A13: 260408-014 | B13: =IFERROR(INDEX(Movimientos!$C$2:$C$1993,MATCH(A13&"ENTRADA",Movimientos!$R$2:$R$1993,0)),"-") -> Starane Xtra | C13: =IFERROR(INDEX(Movimientos!$D$2:$D$1993,MATCH(A13&"ENTRADA",Movimientos!$R$2:$R$1993,0)),"-") -> Fluroxypyr Meptil 45,52% | D13: =IFERROR(INDEX(Movimientos!$E$2:$E$1993,MATCH(A13&"ENTRADA",Movimientos!$R$2:$R$1993,0)),"-") -> Herbicida | E13: =IFERROR(INDEX(Movimientos!$F$2:$F$1993,MATCH(A13&"ENTRADA",Movimientos!$R$2:$R$1993,0)),"-") -> Postemergente | F13: =IFERROR(INDEX(Movimientos!$G$2:$G$1993,MATCH(A13&"ENTRADA",Movimientos!$R$2:$R$1993,0)),"-") -> GS Agro | G13: =IFERROR(INDEX(Movimientos!$L$2:$L$1993,MATCH(A13&"ENTRADA",Movimientos!$R$2:$R$1993,0)),"-") -> L | H13: =IFERROR(IF(INDEX(Movimientos!$M$2:$M$1993,MATCH(A13&"ENTRADA",Movimientos!$R$2:$R$1993,0))=0,"S/D",INDEX(Movimientos!$M$2:$M$1993,MATCH(A13&"ENTRADA",Movimientos!$R$2:$R$1993,0))),"S/D") -> 46509 | I13: =IF(OR(A13="",H13="S/D"),"S/D",H13-TODAY()) -> 200 | J13: =IF(A13="","",SUMIFS(Movimientos!$K:$K,Movimientos!$H:$H,A13)) -> 0 | K13: =IF(A13="","",IF(J13<0.01,"SIN STOCK",IF(H13="S/D","OK",IF(H13<TODAY(),"VENCIDO",IF(I13>=180,"OK","PRÓXIMO A VENCER"))))) -> SIN STOCK
... A57: 260429-105 | B57: =IFERROR(INDEX(Movimientos!$C$2:$C$1993,MATCH(A57&"ENTRADA",Movimientos!$R$2:$R$1993,0)),"-") -> Silobolsa | C57: =IFERROR(INDEX(Movimientos!$D$2:$D$1993,MATCH(A57&"ENTRADA",Movimientos!$R$2:$R$1993,0)),"-") -> Silobolsa 9 pies | D57: =IFERROR(INDEX(Movimientos!$E$2:$E$1993,MATCH(A57&"ENTRADA",Movimientos!$R$2:$R$1993,0)),"-") -> Silobolsa | E57: =IFERROR(INDEX(Movimientos!$F$2:$F$1993,MATCH(A57&"ENTRADA",Movimientos!$R$2:$R$1993,0)),"-") -> 0 | F57: =IFERROR(INDEX(Movimientos!$G$2:$G$1993,MATCH(A57&"ENTRADA",Movimientos!$R$2:$R$1993,0)),"-") -> AYP Agrogestiones | G57: =IFERROR(INDEX(Movimientos!$L$2:$L$1993,MATCH(A57&"ENTRADA",Movimientos!$R$2:$R$1993,0)),"-") -> unidad | H57: =IFERROR(IF(INDEX(Movimientos!$M$2:$M$1993,MATCH(A57&"ENTRADA",Movimientos!$R$2:$R$1993,0))=0,"S/D",INDEX(Movimientos!$M$2:$M$1993,MATCH(A57&"ENTRADA",Movimientos!$R$2:$R$1993,0))),"S/D") -> S/D | I57: =IF(OR(A57="",H57="S/D"),"S/D",H57-TODAY()) -> S/D | J57: =IF(A57="","",SUMIFS(Movimientos!$K:$K,Movimientos!$H:$H,A57)) -> 0 | K57: =IF(A57="","",IF(J57<0.01,"SIN STOCK",IF(H57="S/D","OK",IF(H57<TODAY(),"VENCIDO",IF(I57>=180,"OK","PRÓXIMO A VENCER"))))) -> SIN STOCK
